<?xml version="1.0" ?>
<!-- Generated using onshape-to-robot -->
<!-- Onshape https://cad.onshape.com/documents/89d56f62cbec5e4e914a96f1/w/b118536c27c0a895e8b92c2e/e/b15c13f495d40a52ea5ff85e -->
<robot name="onshape_model">
  <!-- Link base_link -->
  <link name="base_link">
    <inertial>
      <origin xyz="0.00110852 -4.60413e-05 0.0665281" rpy="0 0 0"/>
      <mass value="6.02365"/>
      <inertia ixx="0.0258641" ixy="-7.02344e-05" ixz="0.00181846" iyy="0.0540089" iyz="5.06161e-05" izz="0.0696575"/>
    </inertial>
    <!-- Part base_link -->
    <visual>
      <origin xyz="0.00301282 1.98005e-05 0" rpy="0 -0 0"/>
      <geometry>
        <mesh filename="package://rover_description/meshes/base_link.stl"/>
      </geometry>
      <material name="base_link_material">
        <color rgba="0.737255 0.937255 0.917647 1"/>
      </material>
    </visual>
    <collision>
      <origin xyz="0.00301282 1.98005e-05 0" rpy="0 -0 0"/>
      <geometry>
        <mesh filename="package://rover_description/meshes/base_link.stl"/>
      </geometry>
    </collision>
  </link>
  <!-- Link frame -->
  <link name="frame">
    <inertial>
      <origin xyz="0 0 0" rpy="0 0 0"/>
      <mass value="1e-09"/>
      <inertia ixx="1e-09" ixy="0" ixz="0" iyy="1e-09" iyz="0" izz="1e-09"/>
    </inertial>
    <!-- Part frame -->
    <visual>
      <origin xyz="0 0 0.096" rpy="3.14159 -0 0"/>
      <geometry>
        <mesh filename="package://rover_description/meshes/frame.stl"/>
      </geometry>
      <material name="frame_material">
        <color rgba="0.917647 0.917647 0.917647 1"/>
      </material>
    </visual>
    <collision>
      <origin xyz="0 0 0.096" rpy="3.14159 -0 0"/>
      <geometry>
        <mesh filename="package://rover_description/meshes/frame.stl"/>
      </geometry>
    </collision>
  </link>
  <!-- Joint from base_link to frame -->
  <joint name="base_footprint_joint" type="fixed">
    <origin xyz="-0 0 0.096" rpy="3.14159 -0 0"/>
    <parent link="base_link"/>
    <child link="frame"/>
    <axis xyz="0 0 1"/>
    <limit effort="10" velocity="10"/>
  </joint>
  <!-- Link lidar_link -->
  <link name="lidar_link">
    <inertial>
      <origin xyz="-0.000664365 -0.000288076 -0.00905124" rpy="0 0 0"/>
      <mass value="0.0635195"/>
      <inertia ixx="1.58017e-05" ixy="2.80196e-07" ixz="5.316e-08" iyy="1.59157e-05" iyz="2.3062e-08" izz="2.81689e-05"/>
    </inertial>
    <!-- Part lidar_link -->
    <visual>
      <origin xyz="-0.0760794 -0.0005 -0.144" rpy="0 -0 0"/>
      <geometry>
        <mesh filename="package://rover_description/meshes/lidar_link.stl"/>
      </geometry>
      <material name="lidar_link_material">
        <color rgba="0.231373 0.380392 0.705882 1"/>
      </material>
    </visual>
    <collision>
      <origin xyz="-0.0760794 -0.0005 -0.144" rpy="0 -0 0"/>
      <geometry>
        <mesh filename="package://rover_description/meshes/lidar_link.stl"/>
      </geometry>
    </collision>
  </link>
  <!-- Joint from base_link to lidar_link -->
  <joint name="lidar_joint" type="fixed">
    <origin xyz="0.0790922 0.000519801 0.144" rpy="0 -0 0"/>
    <parent link="base_link"/>
    <child link="lidar_link"/>
    <axis xyz="0 0 1"/>
    <limit effort="10" velocity="10"/>
  </joint>
  <!-- Link camera_link -->
  <link name="camera_link">
    <inertial>
      <origin xyz="-0 -0 -0.0001" rpy="0 0 0"/>
      <mass value="9.11538e-06"/>
      <inertia ixx="1e-09" ixy="-0" ixz="0" iyy="1e-09" iyz="-0" izz="1e-09"/>
    </inertial>
    <!-- Part camera_link -->
    <visual>
      <origin xyz="-0.233035 -0.00325 0.163274" rpy="-3.14159 -1.44547 0"/>
      <geometry>
        <mesh filename="package://rover_description/meshes/camera_link.stl"/>
      </geometry>
      <material name="camera_link_material">
        <color rgba="0.647059 0.647059 0.647059 1"/>
      </material>
    </visual>
    <collision>
      <origin xyz="-0.233035 -0.00325 0.163274" rpy="-3.14159 -1.44547 0"/>
      <geometry>
        <mesh filename="package://rover_description/meshes/camera_link.stl"/>
      </geometry>
    </collision>
  </link>
  <!-- Joint from base_link to camera_link -->
  <joint name="camera_joint" type="fixed">
    <origin xyz="-0.129802 -0.0032302 0.25161" rpy="-1.69612 -0 -1.5708"/>
    <parent link="base_link"/>
    <child link="camera_link"/>
    <axis xyz="0 0 1"/>
    <limit effort="10" velocity="10"/>
  </joint>
  <!-- Link wheel -->
  <link name="wheel">
    <inertial>
      <origin xyz="-0 -0 -0.0040025" rpy="0 0 0"/>
      <mass value="0.0659595"/>
      <inertia ixx="2.10606e-05" ixy="0" ixz="0" iyy="2.10606e-05" iyz="0" izz="3.68034e-05"/>
    </inertial>
    <!-- Part wheel -->
    <visual>
      <origin xyz="-0.0045 -0.032 0.099" rpy="-1.5708 0 0"/>
      <geometry>
        <mesh filename="package://rover_description/meshes/wheel.stl"/>
      </geometry>
      <material name="wheel_material">
        <color rgba="1 0.756863 0.054902 1"/>
      </material>
    </visual>
    <collision>
      <origin xyz="-0.0045 -0.032 0.099" rpy="-1.5708 0 0"/>
      <geometry>
        <mesh filename="package://rover_description/meshes/wheel.stl"/>
      </geometry>
    </collision>
  </link>
  <!-- Joint from base_link to wheel -->
  <joint name="right_wheel_joint" type="continuous">
    <origin xyz="0.00751282 -0.0989802 0.032" rpy="-1.5708 -0 -0"/>
    <parent link="base_link"/>
    <child link="wheel"/>
    <axis xyz="0 0 1"/>
    <limit effort="10" velocity="10"/>
  </joint>
  <!-- Link wheel_2 -->
  <link name="wheel_2">
    <inertial>
      <origin xyz="-0 0 0.0040025" rpy="0 0 0"/>
      <mass value="0.0659595"/>
      <inertia ixx="2.10606e-05" ixy="0" ixz="-0" iyy="2.10606e-05" iyz="0" izz="3.68034e-05"/>
    </inertial>
    <!-- Part wheel_2 -->
    <visual>
      <origin xyz="-0.0045 0.032 -0.099" rpy="1.5708 -0 0"/>
      <geometry>
        <mesh filename="package://rover_description/meshes/wheel.stl"/>
      </geometry>
      <material name="wheel_2_material">
        <color rgba="1 0.756863 0.054902 1"/>
      </material>
    </visual>
    <collision>
      <origin xyz="-0.0045 0.032 -0.099" rpy="1.5708 -0 0"/>
      <geometry>
        <mesh filename="package://rover_description/meshes/wheel.stl"/>
      </geometry>
    </collision>
  </link>
  <!-- Joint from base_link to wheel_2 -->
  <joint name="left_wheel_joint" type="continuous">
    <origin xyz="0.00751282 0.0990198 0.032" rpy="-1.5708 -0 -0"/>
    <parent link="base_link"/>
    <child link="wheel_2"/>
    <axis xyz="0 0 1"/>
    <limit effort="10" velocity="10"/>
  </joint>
</robot>
